<?xml version="1.0"?>
<robot name="blgripper">
  <link name="gripperbase">
    <visual>
    <origin xyz="0 0 0" rpy="1.5708 0 0" />
        <geometry>
            <mesh filename="finBase.STL" scale="0.001 0.001 0.001"/>  
        </geometry>
        <material name="black">
            <color rgba="0.50 0.5 0.5 5.0"/>
        </material>
    </visual>
    <collision>
    <origin xyz="0 0 0" rpy="1.5708 0 0" />
        <geometry>
             <mesh filename="finBase.STL" scale="0.001 0.001 0.001"/>  
        </geometry>
    </collision> 

    <inertial>
      <mass value="0.1"/>
      <inertia ixx="0.001" ixy="0.0" ixz="0.0" iyy="0.001" iyz="0.0" izz="0.001"/>
    </inertial>
  </link>


  <joint name="jl" type="prismatic">
        <axis xyz="1 0 0" /> 
        <limit effort="300.0" velocity="0.012" lower="0.0" upper="0.0495"/>
        <origin xyz="0 0 0" rpy="0 0 0" />
  <parent link="gripperbase" />
  <child link="linkl" />

  </joint>

    <link name="linkl">
   <contact>
      <friction_anchor/>
      <stiffness value="30000.0"/>
      <damping value="1000.0"/>
      <spinning_friction value="1.1"/>
      <lateral_friction value="10.0"/>
    </contact>
    <visual>
    <origin xyz="0 0 0.001" rpy="1.5708 0 0" />
        <geometry>
            <mesh filename="finLeft.STL" scale="0.001 0.001 0.001"/>  
        </geometry>
        <material name="blue">
            <color rgba="0.0 0.2 0.7 5.0"/>
        </material>     
    </visual>
    <collision>
    <origin xyz="0 0 0.001" rpy="1.5708 0 0" />
        <geometry>
            <mesh filename="finLeft.STL" scale="0.001 0.001 0.001"/>  
        </geometry>
    </collision>
    <inertial>
      <mass value="0.0025"/>
      <inertia ixx="0.1" ixy="0.0" ixz="0.0" iyy="0.1" iyz="0.0" izz="0.1"/>
    </inertial>

  </link>


  <joint name="jr" type="prismatic">
        <axis xyz="1 0 0" /> 
        <limit effort="300.0" velocity="0.012" lower="-0.0495" upper="0.0"/>
        <origin xyz="0 0 0" rpy="0 0 0" />
  <parent link="gripperbase" />
  <child link="linkr" />

  </joint>

    <link name="linkr">
   <contact>
      <friction_anchor/>
      <stiffness value="30000.0"/>
      <damping value="1000.0"/>
      <spinning_friction value="1.1"/>
      <lateral_friction value="10.0"/>
    </contact>
    <visual>
    <origin xyz="0 0 0.001" rpy="1.5708 0 0" />
        <geometry>
            <mesh filename="finRight.STL" scale="0.001 0.001 0.001"/>  
        </geometry>
        <material name="blue">
            <color rgba="0.0 0.2 0.7 5.0"/>
        </material>
    </visual>
    <collision>
    <origin xyz="0 0 0.001" rpy="1.5708 0 0" />
        <geometry>
            <mesh filename="finRight.STL" scale="0.001 0.001 0.001"/>  
        </geometry>
    </collision>
    <inertial>
    <mass value="0.0025"/>
      <inertia ixx="0.1" ixy="0.0" ixz="0.0" iyy="0.1" iyz="0.0" izz="0.1"/>
    </inertial>
     
  </link>
</robot> 
